{"name": "test_frame_invalid_dimensions", "status": "failed", "statusDetails": {"message": "Failed: DID NOT RAISE (<class 'ValueError'>, <class 'AttributeError'>)", "trace": "C:\\Workspace-local\\PlainsightAI-takehome\\qa_tests\\unit\\test_frame_unit.py:109: in test_frame_invalid_dimensions\n    ???\nE   Failed: DID NOT RAISE (<class 'ValueError'>, <class 'AttributeError'>)"}, "description": "Test frame handling with invalid dimensions.", "start": 1751312149738, "stop": 1751312149738, "uuid": "87efa1eb-c5d5-4125-add8-fb734d420d1e", "historyId": "da61627c637d663336bd25db7cfb1a29", "testCaseId": "da61627c637d663336bd25db7cfb1a29", "fullName": "unit.test_frame_unit.TestFrameOperations#test_frame_invalid_dimensions", "labels": [{"name": "tag", "value": "bug_discovery"}, {"name": "tag", "value": "pyramid_unit"}, {"name": "tag", "value": "unit"}, {"name": "parentSuite", "value": "unit"}, {"name": "suite", "value": "test_frame_unit"}, {"name": "subSuite", "value": "TestFrameOperations"}, {"name": "host", "value": "fealfr"}, {"name": "thread", "value": "30472-MainThread"}, {"name": "framework", "value": "pytest"}, {"name": "language", "value": "cpython3"}, {"name": "package", "value": "unit.test_frame_unit"}]}