{"name": "Test workflow error recovery - Bug Discovery", "status": "failed", "statusDetails": {"message": "AssertionError: assert 'completed' == 'partially_completed'\n  \n  - partially_completed\n  + completed", "trace": "C:\\Workspace-local\\PlainsightAI-takehome\\qa_tests\\end_to_end\\test_user_scenarios.py:166: in test_workflow_error_recovery_bug\n    ???\nE   AssertionError: assert 'completed' == 'partially_completed'\nE     \nE     - partially_completed\nE     + completed"}, "description": "Bug discovery: workflows don't recover from errors properly", "start": 1751312137752, "stop": 1751312138753, "uuid": "ce937331-2a44-41bb-b756-740434a2da5c", "historyId": "efdac158f3ef6eeac58f5d2a654c3d29", "testCaseId": "efdac158f3ef6eeac58f5d2a654c3d29", "fullName": "end_to_end.test_user_scenarios.TestCompleteUserScenarios#test_workflow_error_recovery_bug", "labels": [{"name": "epic", "value": "OpenFilter QA"}, {"name": "severity", "value": "blocker"}, {"name": "feature", "value": "User Scenarios"}, {"name": "story", "value": "Complete User Workflows"}, {"name": "tag", "value": "bug_discovery"}, {"name": "tag", "value": "pyramid_functional"}, {"name": "tag", "value": "functional"}, {"name": "parentSuite", "value": "end_to_end"}, {"name": "suite", "value": "test_user_scenarios"}, {"name": "subSuite", "value": "TestCompleteUserScenarios"}, {"name": "host", "value": "fealfr"}, {"name": "thread", "value": "30472-MainThread"}, {"name": "framework", "value": "pytest"}, {"name": "language", "value": "cpython3"}, {"name": "package", "value": "end_to_end.test_user_scenarios"}]}