{"name": "test_filter_memory_release", "status": "failed", "statusDetails": {"message": "AssertionError: Expected 'collect' to have been called.", "trace": "C:\\Python312\\Lib\\unittest\\mock.py:916: in assert_called\n    raise AssertionError(msg)\nE   AssertionError: Expected 'collect' to have been called.\n\nDuring handling of the above exception, another exception occurred:\nC:\\Workspace-local\\PlainsightAI-takehome\\qa_tests\\unit\\test_filter_clean.py:39: in test_filter_memory_release\n    ???\nE   AssertionError: Expected 'collect' to have been called."}, "description": "Test memory release during cleanup.", "start": 1751312149610, "stop": 1751312149611, "uuid": "33962edc-fffa-45ec-a080-a49f6ee935f6", "historyId": "22cbc4a2fc6bc0f1b1f6f50a555d6291", "testCaseId": "22cbc4a2fc6bc0f1b1f6f50a555d6291", "fullName": "unit.test_filter_clean.TestFilterCleanup#test_filter_memory_release", "labels": [{"name": "tag", "value": "pyramid_unit"}, {"name": "tag", "value": "unit"}, {"name": "parentSuite", "value": "unit"}, {"name": "suite", "value": "test_filter_clean"}, {"name": "subSuite", "value": "TestFilterCleanup"}, {"name": "host", "value": "fealfr"}, {"name": "thread", "value": "30472-MainThread"}, {"name": "framework", "value": "pytest"}, {"name": "language", "value": "cpython3"}, {"name": "package", "value": "unit.test_filter_clean"}]}